<?xml version="1.0" encoding="utf-8"?>
<!-- This URDF was automatically created by SolidWorks to URDF Exporter! Originally created by Stephen Brawner (brawner@gmail.com) 
     Commit Version: 1.5.1-0-g916b5db  Build Version: 1.5.7152.31018
     For more information, please see http://wiki.ros.org/sw_urdf_exporter -->
<robot
  name="grasshopper_v16">

  <link
    name="body">
    <inertial>
      <origin
        xyz="0.01628 3.7835E-10 0.01505"
        rpy="0 0 0" />
      <mass
        value="0.00568" />
      <inertia
        ixx="5.6329E-07"
        ixy="-7.7524E-14"
        ixz="-5.4963E-07"
        iyy="4.4141E-06"
        iyz="-1.066E-13"
        izz="4.2627E-06" />
    </inertial>
    <visual>
      <origin
        xyz="0 0 0"
        rpy="0 0 0" />
      <geometry>
        <mesh
          filename="package://grasshopper_v16/meshes/body.STL" />
      </geometry>
      <material
        name="yellow">
        <color
          rgba="1 1 0 1" />
      </material>
    </visual>
    <collision>
      <origin
        xyz="0 0 0"
        rpy="0 0 0" />
      <geometry>
        <mesh
          filename="package://grasshopper_v16/meshes/body.STL" />
      </geometry>
    </collision>
  </link>

  <link
    name="lrt">
    <inertial>
      <origin
        xyz="0.026129 8.6736E-18 0.0040288"
        rpy="0 0 0" />
      <mass
        value="0.0010251" />
      <inertia
        ixx="2.7587E-08"
        ixy="-1.0024E-22"
        ixz="6.3727E-10"
        iyy="3.7993E-07"
        iyz="1.8212E-24"
        izz="3.966E-07" />
    </inertial>
    <visual>
      <origin
        xyz="0 0 0"
        rpy="0 0 0" />
      <geometry>
        <mesh
          filename="package://grasshopper_v16/meshes/lrt.STL" />
      </geometry>
      <material
        name="blue">
        <color
          rgba="0 0 1 1" />
      </material>
    </visual>
    <collision>
      <origin
        xyz="0 0 0"
        rpy="0 0 0" />
      <geometry>
        <mesh
          filename="package://grasshopper_v16/meshes/lrt.STL" />
      </geometry>
    </collision>
  </link>

  <joint
    name="lrt"
    type="revolute">
    <origin
      xyz="0.0015 0.012 0.005"
      rpy="1.5708 0 3.1416" />
    <parent
      link="body" />
    <child
      link="lrt" />
    <axis
      xyz="0 0 1" />
    <limit
      lower="0"
      upper="1.5708"
      effort="100000000"
      velocity="100000000" />
    <dynamics
      damping="0.00001" />
  </joint>

  <link
    name="lrc">
    <inertial>
      <origin
        xyz="0.030924 0.0039218 0.0025"
        rpy="0 0 0" />
      <mass
        value="0.00011285" />
      <inertia
        ixx="2.5092E-10"
        ixy="-2.7294E-10"
        ixz="1.736E-14"
        iyy="3.9191E-08"
        iyz="2.1879E-15"
        izz="3.9215E-08" />
    </inertial>
    <visual>
      <origin
        xyz="0 0 0"
        rpy="0 0 0" />
      <geometry>
        <mesh
          filename="package://grasshopper_v16/meshes/lrc.STL" />
      </geometry>
      <material
        name="red">
        <color
          rgba="1 0 0 1" />
      </material>
    </visual>
    <collision>
      <origin
        xyz="0 0 0"
        rpy="0 0 0" />
      <geometry>
        <mesh
          filename="package://grasshopper_v16/meshes/lrc.STL" />
      </geometry>
    </collision>
  </link>

  <joint
    name="lrc"
    type="revolute">
    <origin
      xyz="0.075 0 0.0015"
      rpy="0 0 -0.063261" />
    <parent
      link="lrt" />
    <child
      link="lrc" />
    <axis
      xyz="0 0 1" />
    <limit
      lower="-2.906"
      upper="0"
      effort="100000000"
      velocity="100000000" />
    <dynamics
      damping="0.00001" />
  </joint>

  <link
    name="lrf">
    <inertial>
      <origin
        xyz="-1.7347E-18 -3.4694E-18 -0.00046191"
        rpy="0 0 0" />
      <mass
        value="0.00013943" />
      <inertia
        ixx="6.7329E-10"
        ixy="1.6009E-26"
        ixz="2.0356E-25"
        iyy="6.7329E-10"
        iyz="6.0666E-28"
        izz="8.023E-10" />
    </inertial>
    <visual>
      <origin
        xyz="0 0 0"
        rpy="0 0 0" />
      <geometry>
        <mesh
          filename="package://grasshopper_v16/meshes/lrf.STL" />
      </geometry>
      <material
        name="cyan">
        <color
          rgba="0 1 1 1" />
      </material>
    </visual>
    <collision>
      <origin
        xyz="0 0 0"
        rpy="0 0 0" />
      <geometry>
        <mesh
          filename="package://grasshopper_v16/meshes/lrf.STL" />
      </geometry>
    </collision>
  </link>

  <joint
    name="lrf"
    type="fixed">
    <origin
      xyz="0.063369 0.0040142 0.0025"
      rpy="1.5708 0 -1.5708" />
    <parent
      link="lrc" />
    <child
      link="lrf" />
    <axis
      xyz="0 0 0" />
  </joint>

  <link
    name="lmj">
    <inertial>
      <origin
        xyz="7.7471E-06 3.4694E-18 0.0020001"
        rpy="0 0 0" />
      <mass
        value="1.3465E-05" />
      <inertia
        ixx="5.2603E-11"
        ixy="5.6071E-27"
        ixz="-3.2237E-15"
        iyy="5.5264E-11"
        iyz="1.3527E-28"
        izz="7.2052E-11" />
    </inertial>
    <visual>
      <origin
        xyz="0 0 0"
        rpy="0 0 0" />
      <geometry>
        <mesh
          filename="package://grasshopper_v16/meshes/lmj.STL" />
      </geometry>
      <material
        name="green">
        <color
          rgba="0 1 0 1" />
      </material>
    </visual>
    <collision>
      <origin
        xyz="0 0 0"
        rpy="0 0 0" />
      <geometry>
        <mesh
          filename="package://grasshopper_v16/meshes/lmj.STL" />
      </geometry>
    </collision>
  </link>

  <joint
    name="lmj"
    type="revolute">
    <origin
      xyz="0.0195 0.0125 0.003"
      rpy="0 0 1.5708" />
    <parent
      link="body" />
    <child
      link="lmj" />
    <axis
      xyz="0 0 1" />
    <limit
      lower="-1.3963"
      upper="0.95993"
      effort="10000"
      velocity="10000" />
  </joint>

  <link
    name="lmt">
    <inertial>
      <origin
        xyz="0.012787 -0.0037196 -1.1737E-08"
        rpy="0 0 0" />
      <mass
        value="3.6611E-05" />
      <inertia
        ixx="6.8527E-11"
        ixy="4.4234E-11"
        ixz="-1.9814E-15"
        iyy="2.1403E-09"
        iyz="5.0977E-16"
        izz="2.1458E-09" />
    </inertial>
    <visual>
      <origin
        xyz="0 0 0"
        rpy="0 0 0" />
      <geometry>
        <mesh
          filename="package://grasshopper_v16/meshes/lmt.STL" />
      </geometry>
      <material
        name="blue">
        <color
          rgba="0 0 1 1" />
      </material>
    </visual>
    <collision>
      <origin
        xyz="0 0 0"
        rpy="0 0 0" />
      <geometry>
        <mesh
          filename="package://grasshopper_v16/meshes/lmt.STL" />
      </geometry>
    </collision>
  </link>

  <joint
    name="lmt"
    type="revolute">
    <origin
      xyz="0.0035 0 0.002"
      rpy="1.5708 -0.13685 0" />
    <parent
      link="lmj" />
    <child
      link="lmt" />
    <axis
      xyz="0 0 1" />
    <limit
      lower="0"
      upper="1.5708"
      effort="10000"
      velocity="10000" />
  </joint>

  <link
    name="lmc">
    <inertial>
      <origin
        xyz="0.012337 0.0035222 2.1681E-10"
        rpy="0 0 0" />
      <mass
        value="3.5662E-05" />
      <inertia
        ixx="6.2989E-11"
        ixy="-2.0946E-11"
        ixz="8.088E-17"
        iyy="1.9097E-09"
        iyz="6.3655E-17"
        izz="1.9164E-09" />
    </inertial>
    <visual>
      <origin
        xyz="0 0 0"
        rpy="0 0 0" />
      <geometry>
        <mesh
          filename="package://grasshopper_v16/meshes/lmc.STL" />
      </geometry>
      <material
        name="red">
        <color
          rgba="1 0 0 1" />
      </material>
    </visual>
    <collision>
      <origin
        xyz="0 0 0"
        rpy="0 0 0" />
      <geometry>
        <mesh
          filename="package://grasshopper_v16/meshes/lmc.STL" />
      </geometry>
    </collision>
  </link>

  <joint
    name="lmc"
    type="revolute">
    <origin
      xyz="0.027871 -0.0038382 0"
      rpy="0 0 -0.27932" />
    <parent
      link="lmt" />
    <child
      link="lmc" />
    <axis
      xyz="0 0 1" />
    <limit
      lower="-2.7838"
      upper="0"
      effort="10000"
      velocity="10000" />
  </joint>

  <link
    name="lmf">
    <inertial>
      <origin
        xyz="-3.4694E-18 -1.7347E-18 -0.00036944"
        rpy="0 0 0" />
      <mass
        value="0.00014644" />
      <inertia
        ixx="7.1592E-10"
        ixy="2.5849E-26"
        ixz="9.0473E-26"
        iyy="7.1592E-10"
        iyz="3.8774E-26"
        izz="8.2767E-10" />
    </inertial>
    <visual>
      <origin
        xyz="0 0 0"
        rpy="0 0 0" />
      <geometry>
        <mesh
          filename="package://grasshopper_v16/meshes/lmf.STL" />
      </geometry>
      <material
        name="cyan">
        <color
          rgba="0 1 1 1" />
      </material>
    </visual>
    <collision>
      <origin
        xyz="0 0 0"
        rpy="0 0 0" />
      <geometry>
        <mesh
          filename="package://grasshopper_v16/meshes/lmf.STL" />
      </geometry>
    </collision>
  </link>

  <joint
    name="lmf"
    type="fixed">
    <origin
      xyz="0.024991154273188 0.00358467875173177 0"
      rpy="-1.5707963267949 -0.489454769549356 1.5707963267949" />
    <parent
      link="lmc" />
    <child
      link="lmf" />
    <axis
      xyz="0 0 0" />
  </joint>

  <link
    name="lfj">
    <inertial>
      <origin
        xyz="7.7471E-06 -1.3878E-17 0.0020001"
        rpy="0 0 0" />
      <mass
        value="1.3465E-05" />
      <inertia
        ixx="5.2603E-11"
        ixy="3.9623E-27"
        ixz="-3.2237E-15"
        iyy="5.5264E-11"
        iyz="-7.2343E-27"
        izz="7.2052E-11" />
    </inertial>
    <visual>
      <origin
        xyz="0 0 0"
        rpy="0 0 0" />
      <geometry>
        <mesh
          filename="package://grasshopper_v16/meshes/lfj.STL" />
      </geometry>
      <material
        name="green">
        <color
          rgba="0 1 0 1" />
      </material>
    </visual>
    <collision>
      <origin
        xyz="0 0 0"
        rpy="0 0 0" />
      <geometry>
        <mesh
          filename="package://grasshopper_v16/meshes/lfj.STL" />
      </geometry>
    </collision>
  </link>

  <joint
    name="lfj"
    type="revolute">
    <origin
      xyz="0.038 0.005 0.003"
      rpy="0 0 1.5708" />
    <parent
      link="body" />
    <child
      link="lfj" />
    <axis
      xyz="0 0 1" />
    <limit
      lower="-1.2217"
      upper="0.7854"
      effort="10000"
      velocity="10000" />
  </joint>
  <link
    name="lft">
    <inertial>
      <origin
        xyz="0.012295 -0.0037175 -1.1505E-08"
        rpy="0 0 0" />
      <mass
        value="3.516E-05" />
      <inertia
        ixx="6.6056E-11"
        ixy="4.2264E-11"
        ixz="-1.8246E-15"
        iyy="1.9095E-09"
        iyz="4.7256E-16"
        izz="1.9149E-09" />
    </inertial>
    <visual>
      <origin
        xyz="0 0 0"
        rpy="0 0 0" />
      <geometry>
        <mesh
          filename="package://grasshopper_v16/meshes/lft.STL" />
      </geometry>
      <material
        name="blue">
        <color
          rgba="0 0 1 1" />
      </material>
    </visual>
    <collision>
      <origin
        xyz="0 0 0"
        rpy="0 0 0" />
      <geometry>
        <mesh
          filename="package://grasshopper_v16/meshes/lft.STL" />
      </geometry>
    </collision>
  </link>

  <joint
    name="lft"
    type="revolute">
    <origin
      xyz="0.0035 0 0.002"
      rpy="1.5708 -0.14188 0" />
    <parent
      link="lfj" />
    <child
      link="lft" />
    <axis
      xyz="0 0 1" />
    <limit
      lower="0"
      upper="1.5708"
      effort="10000"
      velocity="10000" />
  </joint>

  <link
    name="lfc">
    <inertial>
      <origin
        xyz="0.012346 0.0035298 9.2442E-11"
        rpy="0 0 0" />
      <mass
        value="3.5516E-05" />
      <inertia
        ixx="6.2427E-11"
        ixy="-2.0323E-11"
        ixz="5.592E-17"
        iyy="1.9089E-09"
        iyz="5.073E-17"
        izz="1.9151E-09" />
    </inertial>
    <visual>
      <origin
        xyz="0 0 0"
        rpy="0 0 0" />
      <geometry>
        <mesh
          filename="package://grasshopper_v16/meshes/lfc.STL" />
      </geometry>
      <material
        name="red">
        <color
          rgba="1 0 0 1" />
      </material>
    </visual>
    <collision>
      <origin
        xyz="0 0 0"
        rpy="0 0 0" />
      <geometry>
        <mesh
          filename="package://grasshopper_v16/meshes/lfc.STL" />
      </geometry>
    </collision>
  </link>

  <joint
    name="lfc"
    type="revolute">
    <origin
      xyz="0.026871 -0.0038382 0"
      rpy="0 0 -0.28434" />
    <parent
      link="lft" />
    <child
      link="lfc" />
    <axis
      xyz="0 0 1" />
    <limit
      lower="-2.7838"
      upper="0"
      effort="10000"
      velocity="10000" />
  </joint>

  <link
    name="lff">
    <inertial>
      <origin
        xyz="6.9389E-18 1.7347E-18 -0.00036944"
        rpy="0 0 0" />
      <mass
        value="0.00014644" />
      <inertia
        ixx="7.1592E-10"
        ixy="0"
        ixz="7.2701E-26"
        iyy="7.1592E-10"
        iyz="6.4623E-27"
        izz="8.2767E-10" />
    </inertial>
    <visual>
      <origin
        xyz="0 0 0"
        rpy="0 0 0" />
      <geometry>
        <mesh
          filename="package://grasshopper_v16/meshes/lff.STL" />
      </geometry>
      <material
        name="cyan">
        <color
          rgba="0 1 1 1" />
      </material>
    </visual>
    <collision>
      <origin
        xyz="0 0 0"
        rpy="0 0 0" />
      <geometry>
        <mesh
          filename="package://grasshopper_v16/meshes/lff.STL" />
      </geometry>
    </collision>
  </link>

  <joint
    name="lff"
    type="fixed">
    <origin
      xyz="0.024991154273188 0.00358467875173176 0"
      rpy="-1.5707963267949 -1.31216908789752 1.5707963267949" />
    <parent
      link="lfc" />
    <child
      link="lff" />
    <axis
      xyz="0.336925099006697 0.628632687727636 -0.700929683762682" />
  </joint>

  <link
    name="rrt">
    <inertial>
      <origin
        xyz="0.026129 2.6021E-18 -0.0040288"
        rpy="0 0 0" />
      <mass
        value="0.0010251" />
      <inertia
        ixx="2.7587E-08"
        ixy="-5.2128E-23"
        ixz="-6.3727E-10"
        iyy="3.7993E-07"
        iyz="2.7401E-25"
        izz="3.966E-07" />
    </inertial>
    <visual>
      <origin
        xyz="0 0 0"
        rpy="0 0 0" />
      <geometry>
        <mesh
          filename="package://grasshopper_v16/meshes/rrt.STL" />
      </geometry>
      <material
        name="blue">
        <color
          rgba="0 0 1 1" />
      </material>
    </visual>
    <collision>
      <origin
        xyz="0 0 0"
        rpy="0 0 0" />
      <geometry>
        <mesh
          filename="package://grasshopper_v16/meshes/rrt.STL" />
      </geometry>
    </collision>
  </link>

  <joint
    name="rrt"
    type="revolute">
    <origin
      xyz="0.0015 -0.012 0.005"
      rpy="1.5708 0 3.1416" />
    <parent
      link="body" />
    <child
      link="rrt" />
    <axis
      xyz="0 0 1" />
    <limit
      lower="0"
      upper="1.5708"
      effort="100000000"
      velocity="100000000" />
    <dynamics
      damping="0.00001" />
  </joint>

  <link
    name="rrc">
    <inertial>
      <origin
        xyz="0.030924 0.0039218 -0.0025"
        rpy="0 0 0" />
      <mass
        value="0.00011285" />
      <inertia
        ixx="2.5092E-10"
        ixy="-2.7294E-10"
        ixz="1.736E-14"
        iyy="3.9191E-08"
        iyz="2.1879E-15"
        izz="3.9215E-08" />
    </inertial>
    <visual>
      <origin
        xyz="0 0 0"
        rpy="0 0 0" />
      <geometry>
        <mesh
          filename="package://grasshopper_v16/meshes/rrc.STL" />
      </geometry>
      <material
        name="red">
        <color
          rgba="1 0 0 1" />
      </material>
    </visual>
    <collision>
      <origin
        xyz="0 0 0"
        rpy="0 0 0" />
      <geometry>
        <mesh
          filename="package://grasshopper_v16/meshes/rrc.STL" />
      </geometry>
    </collision>
  </link>

  <joint
    name="rrc"
    type="revolute">
    <origin
      xyz="0.075 0 -0.0015"
      rpy="0 0 -0.063261" />
    <parent
      link="rrt" />
    <child
      link="rrc" />
    <axis
      xyz="0 0 1" />
    <limit
      lower="-2.906"
      upper="0"
      effort="100000000"
      velocity="100000000" />
    <dynamics
      damping="0.00001" />
  </joint>

  <link
    name="rrf">
    <inertial>
      <origin
        xyz="-1.7347E-18 0 -0.00046191"
        rpy="0 0 0" />
      <mass
        value="0.00013943" />
      <inertia
        ixx="6.7329E-10"
        ixy="-1.9541E-29"
        ixz="1.5833E-25"
        iyy="6.7329E-10"
        iyz="1.2684E-26"
        izz="8.023E-10" />
    </inertial>
    <visual>
      <origin
        xyz="0 0 0"
        rpy="0 0 0" />
      <geometry>
        <mesh
          filename="package://grasshopper_v16/meshes/rrf.STL" />
      </geometry>
      <material
        name="cyan">
        <color
          rgba="0 1 1 1" />
      </material>
    </visual>
    <collision>
      <origin
        xyz="0 0 0"
        rpy="0 0 0" />
      <geometry>
        <mesh
          filename="package://grasshopper_v16/meshes/rrf.STL" />
      </geometry>
    </collision>
  </link>

  <joint
    name="rrf"
    type="fixed">
    <origin
      xyz="0.063369 0.0040142 -0.0025"
      rpy="1.5708 0 -1.5708" />
    <parent
      link="rrc" />
    <child
      link="rrf" />
    <axis
      xyz="0 0 0" />
  </joint>

  <link
    name="rmj">
    <inertial>
      <origin
        xyz="7.7471E-06 -3.4694E-18 0.0020001"
        rpy="0 0 0" />
      <mass
        value="1.3465E-05" />
      <inertia
        ixx="5.2603E-11"
        ixy="1.9568E-27"
        ixz="-3.2237E-15"
        iyy="5.5264E-11"
        iyz="-1.5305E-28"
        izz="7.2052E-11" />
    </inertial>
    <visual>
      <origin
        xyz="0 0 0"
        rpy="0 0 0" />
      <geometry>
        <mesh
          filename="package://grasshopper_v16/meshes/rmj.STL" />
      </geometry>
      <material
        name="green">
        <color
          rgba="0 1 0 1" />
      </material>
    </visual>
    <collision>
      <origin
        xyz="0 0 0"
        rpy="0 0 0" />
      <geometry>
        <mesh
          filename="package://grasshopper_v16/meshes/rmj.STL" />
      </geometry>
    </collision>
  </link>

  <joint
    name="rmj"
    type="revolute">
    <origin
      xyz="0.0195 -0.0125 0.003"
      rpy="0 0 -1.5708" />
    <parent
      link="body" />
    <child
      link="rmj" />
    <axis
      xyz="0 0 1" />
    <limit
      lower="-0.95993"
      upper="1.3963"
      effort="10000"
      velocity="10000" />
  </joint>

  <link
    name="rmt">
    <inertial>
      <origin
        xyz="0.012787 -0.0037196 -1.1737E-08"
        rpy="0 0 0" />
      <mass
        value="3.6611E-05" />
      <inertia
        ixx="6.8527E-11"
        ixy="4.4234E-11"
        ixz="-1.9814E-15"
        iyy="2.1403E-09"
        iyz="5.0977E-16"
        izz="2.1458E-09" />
    </inertial>
    <visual>
      <origin
        xyz="0 0 0"
        rpy="0 0 0" />
      <geometry>
        <mesh
          filename="package://grasshopper_v16/meshes/rmt.STL" />
      </geometry>
      <material
        name="blue">
        <color
          rgba="0 0 1 1" />
      </material>
    </visual>
    <collision>
      <origin
        xyz="0 0 0"
        rpy="0 0 0" />
      <geometry>
        <mesh
          filename="package://grasshopper_v16/meshes/rmt.STL" />
      </geometry>
    </collision>
  </link>

  <joint
    name="rmt"
    type="revolute">
    <origin
      xyz="0.0035 0 0.002"
      rpy="1.5708 -0.13685 0" />
    <parent
      link="rmj" />
    <child
      link="rmt" />
    <axis
      xyz="0 0 1" />
    <limit
      lower="0"
      upper="1.5708"
      effort="10000"
      velocity="10000" />
  </joint>

  <link
    name="rmc">
    <inertial>
      <origin
        xyz="0.012337 0.0035222 2.1681E-10"
        rpy="0 0 0" />
      <mass
        value="3.5662E-05" />
      <inertia
        ixx="6.2989E-11"
        ixy="-2.0946E-11"
        ixz="8.088E-17"
        iyy="1.9097E-09"
        iyz="6.3655E-17"
        izz="1.9164E-09" />
    </inertial>
    <visual>
      <origin
        xyz="0 0 0"
        rpy="0 0 0" />
      <geometry>
        <mesh
          filename="package://grasshopper_v16/meshes/rmc.STL" />
      </geometry>
      <material
        name="red">
        <color
          rgba="1 0 0 1" />
      </material>
    </visual>
    <collision>
      <origin
        xyz="0 0 0"
        rpy="0 0 0" />
      <geometry>
        <mesh
          filename="package://grasshopper_v16/meshes/rmc.STL" />
      </geometry>
    </collision>
  </link>

  <joint
    name="rmc"
    type="revolute">
    <origin
      xyz="0.027871 -0.0038382 0"
      rpy="0 0 -0.27932" />
    <parent
      link="rmt" />
    <child
      link="rmc" />
    <axis
      xyz="0 0 1" />
    <limit
      lower="-2.7838"
      upper="0"
      effort="10000"
      velocity="10000" />
  </joint>

  <link
    name="rmf">
    <inertial>
      <origin
        xyz="-3.4694E-18 8.6736E-19 -0.00036944"
        rpy="0 0 0" />
      <mass
        value="0.00014644" />
      <inertia
        ixx="7.1592E-10"
        ixy="0"
        ixz="-9.0473E-26"
        iyy="7.1592E-10"
        iyz="1.0986E-25"
        izz="8.2767E-10" />
    </inertial>
    <visual>
      <origin
        xyz="0 0 0"
        rpy="0 0 0" />
      <geometry>
        <mesh
          filename="package://grasshopper_v16/meshes/rmf.STL" />
      </geometry>
      <material
        name="cyan">
        <color
          rgba="0 1 1 1" />
      </material>
    </visual>
    <collision>
      <origin
        xyz="0 0 0"
        rpy="0 0 0" />
      <geometry>
        <mesh
          filename="package://grasshopper_v16/meshes/rmf.STL" />
      </geometry>
    </collision>
  </link>

  <joint
    name="rmf"
    type="fixed">
    <origin
      xyz="0.024991154273188 0.00358467875173177 0"
      rpy="-1.5707963267949 1.06968702280819 1.5707963267949" />
    <parent
      link="rmc" />
    <child
      link="rmf" />
    <axis
      xyz="0.588477199867477 -0.264058718143646 -0.764177714022378" />
  </joint>

  <link
    name="rfj">
    <inertial>
      <origin
        xyz="7.7471E-06 -3.4694E-17 0.0020001"
        rpy="0 0 0" />
      <mass
        value="1.3465E-05" />
      <inertia
        ixx="5.2603E-11"
        ixy="1.4871E-26"
        ixz="-3.2237E-15"
        iyy="5.5264E-11"
        iyz="-1.3331E-28"
        izz="7.2052E-11" />
    </inertial>
    <visual>
      <origin
        xyz="0 0 0"
        rpy="0 0 0" />
      <geometry>
        <mesh
          filename="package://grasshopper_v16/meshes/rfj.STL" />
      </geometry>
      <material
        name="green">
        <color
          rgba="0 1 0 1" />
      </material>
    </visual>
    <collision>
      <origin
        xyz="0 0 0"
        rpy="0 0 0" />
      <geometry>
        <mesh
          filename="package://grasshopper_v16/meshes/rfj.STL" />
      </geometry>
    </collision>
  </link>

  <joint
    name="rfj"
    type="revolute">
    <origin
      xyz="0.038 -0.005 0.003"
      rpy="0 0 -1.5708" />
    <parent
      link="body" />
    <child
      link="rfj" />
    <axis
      xyz="0 0 1" />
    <limit
      lower="-0.7854"
      upper="1.2217"
      effort="10000"
      velocity="10000" />
  </joint>

  <link
    name="rft">
    <inertial>
      <origin
        xyz="0.012295 -0.0037175 -1.1505E-08"
        rpy="0 0 0" />
      <mass
        value="3.516E-05" />
      <inertia
        ixx="6.6056E-11"
        ixy="4.2264E-11"
        ixz="-1.8246E-15"
        iyy="1.9095E-09"
        iyz="4.7256E-16"
        izz="1.9149E-09" />
    </inertial>
    <visual>
      <origin
        xyz="0 0 0"
        rpy="0 0 0" />
      <geometry>
        <mesh
          filename="package://grasshopper_v16/meshes/rft.STL" />
      </geometry>
      <material
        name="blue">
        <color
          rgba="0 0 1 1" />
      </material>
    </visual>
    <collision>
      <origin
        xyz="0 0 0"
        rpy="0 0 0" />
      <geometry>
        <mesh
          filename="package://grasshopper_v16/meshes/rft.STL" />
      </geometry>
    </collision>
  </link>

  <joint
    name="rft"
    type="revolute">
    <origin
      xyz="0.0035 0 0.002"
      rpy="1.5708 -0.14188 0" />
    <parent
      link="rfj" />
    <child
      link="rft" />
    <axis
      xyz="0 0 1" />
    <limit
      lower="0"
      upper="1.5708"
      effort="10000"
      velocity="10000" />
  </joint>

  <link
    name="rfc">
    <inertial>
      <origin
        xyz="0.012346 0.0035298 9.2442E-11"
        rpy="0 0 0" />
      <mass
        value="3.5516E-05" />
      <inertia
        ixx="6.2427E-11"
        ixy="-2.0323E-11"
        ixz="5.592E-17"
        iyy="1.9089E-09"
        iyz="5.073E-17"
        izz="1.9151E-09" />
    </inertial>
    <visual>
      <origin
        xyz="0 0 0"
        rpy="0 0 0" />
      <geometry>
        <mesh
          filename="package://grasshopper_v16/meshes/rfc.STL" />
      </geometry>
      <material
        name="red">
        <color
          rgba="1 0 0 1" />
      </material>
    </visual>
    <collision>
      <origin
        xyz="0 0 0"
        rpy="0 0 0" />
      <geometry>
        <mesh
          filename="package://grasshopper_v16/meshes/rfc.STL" />
      </geometry>
    </collision>
  </link>

  <joint
    name="rfc"
    type="revolute">
    <origin
      xyz="0.026871 -0.0038382 0"
      rpy="0 0 -0.28434" />
    <parent
      link="rft" />
    <child
      link="rfc" />
    <axis
      xyz="0 0 1" />
    <limit
      lower="-2.7838"
      upper="0"
      effort="10000"
      velocity="10000" />
  </joint>

  <link
    name="rff">
    <inertial>
      <origin
        xyz="0 0 -0.00036944"
        rpy="0 0 0" />
      <mass
        value="0.00014644" />
      <inertia
        ixx="7.1592E-10"
        ixy="2.5849E-26"
        ixz="-1.1632E-25"
        iyy="7.1592E-10"
        iyz="-6.7855E-26"
        izz="8.2767E-10" />
    </inertial>
    <visual>
      <origin
        xyz="0 0 0"
        rpy="0 0 0" />
      <geometry>
        <mesh
          filename="package://grasshopper_v16/meshes/rff.STL" />
      </geometry>
      <material
        name="cyan">
        <color
          rgba="0 1 1 1" />
      </material>
    </visual>
    <collision>
      <origin
        xyz="0 0 0"
        rpy="0 0 0" />
      <geometry>
        <mesh
          filename="package://grasshopper_v16/meshes/rff.STL" />
      </geometry>
    </collision>
  </link>

  <joint
    name="rff"
    type="fixed">
    <origin
      xyz="0.024991154273188 0.00358467875173169 0"
      rpy="-1.5707963267949 0.499594953248322 1.5707963267949" />
    <parent
      link="rfc" />
    <child
      link="rff" />
    <axis
      xyz="0.244519200301658 0.952298530924757 -0.18258660597751" />
  </joint>
</robot>